sudo: unable to resolve host iwgraph
Traceback (most recent call last):
  File "/home/pi/iwgrapher/iwgrapher.py", line 262, in <module>
    main()
  File "/home/pi/iwgrapher/iwgrapher.py", line 259, in main
    parsedb()
  File "/home/pi/iwgrapher/iwgrapher.py", line 111, in parsedb
    client.create_database(data['influx']['db'])
  File "/usr/local/lib/python2.7/dist-packages/influxdb/client.py", line 571, in create_database
    self.query("CREATE DATABASE {0}".format(quote_ident(dbname)))
  File "/usr/local/lib/python2.7/dist-packages/influxdb/client.py", line 409, in query
    expected_response_code=expected_response_code
  File "/usr/local/lib/python2.7/dist-packages/influxdb/client.py", line 267, in request
    timeout=self._timeout
  File "/usr/local/lib/python2.7/dist-packages/requests/sessions.py", line 512, in request
    resp = self.send(prep, **send_kwargs)
  File "/usr/local/lib/python2.7/dist-packages/requests/sessions.py", line 622, in send
    r = adapter.send(request, **kwargs)
  File "/usr/local/lib/python2.7/dist-packages/requests/adapters.py", line 513, in send
    raise ConnectionError(e, request=request)
requests.exceptions.ConnectionError: HTTPConnectionPool(host='192.168.41.209', port=8086): Max retries exceeded with url: /query?q=CREATE+DATABASE+%22wifiStat%22&db=wifiStat (Caused by NewConnectionError('<urllib3.connection.HTTPConnection object at 0x764bd5d0>: Failed to establish a new connection: [Errno 101] Network is unreachable',))
